<?xml version="1.0"?>
<robot name="diff_robot">

  <!-- Base Link -->
  <link name="base_footprint"/>

  <joint name="base_joint" type="fixed">
    <parent link="base_footprint"/>
    <child  link="base_link"/>
    <origin xyz="0 0 0.075" rpy="0 0 0"/>
  </joint>

  <link name="base_link">
    <visual>
      <geometry><box size="0.28 0.28 0.15"/></geometry>
      <material name="blue"><color rgba="0.2 0.4 0.8 1"/></material>
    </visual>
    <collision>
      <geometry><box size="0.28 0.28 0.15"/></geometry>
    </collision>
    <inertial>
      <mass value="2.0"/>
      <inertia ixx="0.0173" ixy="0" ixz="0" iyy="0.0173" iyz="0" izz="0.0320"/>
    </inertial>
  </link>

  <!-- Left Wheel -->
  <joint name="left_wheel_joint" type="continuous">
    <parent link="base_link"/>
    <child  link="left_wheel"/>
    <origin xyz="0 0.15 -0.025" rpy="-1.5707963 0 0"/>
    <axis xyz="0 0 1"/>
  </joint>
  <link name="left_wheel">
    <visual><geometry><cylinder radius="0.05" length="0.04"/></geometry>
      <material name="dark"><color rgba="0.1 0.1 0.1 1"/></material></visual>
    <collision><geometry><cylinder radius="0.05" length="0.04"/></geometry></collision>
    <inertial><mass value="0.3"/>
      <inertia ixx="0.000188" ixy="0" ixz="0" iyy="0.000188" iyz="0" izz="0.000375"/></inertial>
  </link>

  <!-- Right Wheel -->
  <joint name="right_wheel_joint" type="continuous">
    <parent link="base_link"/>
    <child  link="right_wheel"/>
    <origin xyz="0 -0.15 -0.025" rpy="-1.5707963 0 0"/>
    <axis xyz="0 0 1"/>
  </joint>
  <link name="right_wheel">
    <visual><geometry><cylinder radius="0.05" length="0.04"/></geometry>
      <material name="dark"><color rgba="0.1 0.1 0.1 1"/></material></visual>
    <collision><geometry><cylinder radius="0.05" length="0.04"/></geometry></collision>
    <inertial><mass value="0.3"/>
      <inertia ixx="0.000188" ixy="0" ixz="0" iyy="0.000188" iyz="0" izz="0.000375"/></inertial>
  </link>

  <!-- Caster Wheels -->
  <joint name="caster_front_joint" type="fixed">
    <parent link="base_link"/>
    <child  link="caster_front"/>
    <origin xyz="0.1 0 -0.075" rpy="0 0 0"/>
  </joint>
  <link name="caster_front">
    <visual><geometry><sphere radius="0.025"/></geometry></visual>
    <collision><geometry><sphere radius="0.025"/></geometry></collision>
    <inertial><mass value="0.1"/>
      <inertia ixx="0.00001" ixy="0" ixz="0" iyy="0.00001" iyz="0" izz="0.00001"/></inertial>
  </link>

  <joint name="caster_back_joint" type="fixed">
    <parent link="base_link"/>
    <child  link="caster_back"/>
    <origin xyz="-0.1 0 -0.075" rpy="0 0 0"/>
  </joint>
  <link name="caster_back">
    <visual><geometry><sphere radius="0.025"/></geometry></visual>
    <collision><geometry><sphere radius="0.025"/></geometry></collision>
    <inertial><mass value="0.1"/>
      <inertia ixx="0.00001" ixy="0" ixz="0" iyy="0.00001" iyz="0" izz="0.00001"/></inertial>
  </link>

  <!-- LiDAR Link -->
  <joint name="lidar_joint" type="fixed">
    <parent link="base_link"/>
    <child  link="lidar_link"/>
    <origin xyz="0 0 0.1" rpy="0 0 0"/>
  </joint>

  <link name="lidar_link">
    <visual>
      <geometry><cylinder radius="0.04" length="0.04"/></geometry>
      <material name="black"><color rgba="0.05 0.05 0.05 1"/></material>
    </visual>
    <collision>
      <geometry><cylinder radius="0.04" length="0.04"/></geometry>
    </collision>
    <inertial>
      <mass value="0.1"/>
      <inertia ixx="0.00001" ixy="0" ixz="0" iyy="0.00001" iyz="0" izz="0.00001"/>
    </inertial>
  </link>

  <!-- Diff Drive Plugin -->
  <gazebo>
    <plugin name="gazebo_ros_diff_drive" filename="libgazebo_ros_diff_drive.so">
      <ros><namespace>/</namespace></ros>
      <left_joint>left_wheel_joint</left_joint>
      <right_joint>right_wheel_joint</right_joint>
      <wheel_separation>0.30</wheel_separation>
      <wheel_diameter>0.10</wheel_diameter>
      <max_wheel_torque>20</max_wheel_torque>
      <max_wheel_acceleration>1.0</max_wheel_acceleration>
      <command_topic>cmd_vel</command_topic>
      <publish_odom>true</publish_odom>
      <publish_odom_tf>true</publish_odom_tf>
      <publish_wheel_tf>false</publish_wheel_tf>
      <odometry_topic>odom</odometry_topic>
      <odometry_frame>odom</odometry_frame>
      <robot_base_frame>base_footprint</robot_base_frame>
    </plugin>
  </gazebo>

  <!-- 2D LiDAR Plugin -->
  <gazebo reference="lidar_link">
    <sensor name="lidar_sensor" type="ray">
      <always_on>true</always_on>
      <visualize>true</visualize>           
      <update_rate>10</update_rate>        
      <ray>
        <scan>
          <horizontal>
            <samples>360</samples>         
            <resolution>1</resolution>
            <min_angle>-3.14159265</min_angle>
            <max_angle>3.14159265</max_angle>  
          </horizontal>
        </scan>
        <range>
          <min>0.12</min>  
          <max>8.0</max>
          <resolution>0.01</resolution>
        </range>
        <noise>
          <type>gaussian</type>
          <mean>0.0</mean>
          <stddev>0.01</stddev>
        </noise>
      </ray>
      <plugin name="gazebo_ros_lidar" filename="libgazebo_ros_ray_sensor.so">
        <ros>
          <namespace>/</namespace>
          <remapping>~/out:=scan</remapping>
        </ros>
        <output_type>sensor_msgs/LaserScan</output_type>
        <frame_name>lidar_link</frame_name>
      </plugin>
    </sensor>
    <material>Gazebo/Black</material>
  </gazebo>

  <!-- Gazebo Materials -->
  <gazebo reference="base_link"><material>Gazebo/Blue</material></gazebo>
  <gazebo reference="left_wheel"><material>Gazebo/DarkGrey</material></gazebo>
  <gazebo reference="right_wheel"><material>Gazebo/DarkGrey</material></gazebo>
  <gazebo reference="caster_front">
    <material>Gazebo/White</material><mu1>0.0</mu1><mu2>0.0</mu2>
  </gazebo>
  <gazebo reference="caster_back">
    <material>Gazebo/White</material><mu1>0.0</mu1><mu2>0.0</mu2>
  </gazebo>

</robot>
